<?xml version="1.0" encoding="UTF-8"?>

<robot name="myrobot" xmlns:xacro="http://www.ros.org/wiki/xacro">

  <xacro:include filename="$(find mybot_description)/urdf/mybot.gazebo" />
  <xacro:include filename="$(find mybot_description)/urdf/materials.xacro" />
  <xacro:include filename="$(find mybot_description)/urdf/macros.xacro" />

  <link name='chassis'>
    <pose>0 0 0.1 0 0 0</pose>
    
    <inertial>
      <mass value="10"/>
      <origin xyz="0.0 0 0.1" rpy=" 0 0 0"/>
      <inertia
          ixx="0.5" ixy="0" ixz="0"
          iyy="1.0" iyz="0"
          izz="0.1" />
    </inertial>

    <collision name='collision'>
      <geometry>
        <box size="0.362 0.19 .09"/>
      </geometry>
    </collision>

    <visual name='chassis_visual'>
      <origin xyz="0 0 0" rpy=" 0 0 0"/>
      <geometry>
        <box size="0.362 0.19 .09"/>
      </geometry>
    </visual>


    <collision name='caster_collision'>
      <origin xyz="-0.15 0 -0.06" rpy=" 0 0 0"/>
      <geometry>
        <sphere radius="0.03"/>
      </geometry>
      <surface>
        <friction>
          <ode>
            <mu>0</mu>
            <mu2>0</mu2>
            <slip1>1.0</slip1>
            <slip2>1.0</slip2>
          </ode>
        </friction>
      </surface>
    </collision>

    <visual name='caster_visual'>
      <origin xyz="-0.15 0 -0.06" rpy=" 0 0 0"/>
      <geometry>
        <sphere radius="0.03"/>
      </geometry>
    </visual>
  </link>


  <link name="left_wheel"> 
    <!--origin xyz="0.1 0.13 0.1" rpy="0 1.5707 1.5707"/-->
    <collision name="collision">
      <origin xyz="0 0 0" rpy="0 1.5707 1.5707"/>
      <geometry>
        <cylinder radius="0.095" length="0.025"/>
      </geometry>
    </collision>
    <visual name="left_wheel_visual">
      <origin xyz="0 0 0" rpy="0 1.5707 1.5707"/>
      <geometry>
        <cylinder radius="0.095" length="0.025"/>
      </geometry>
    </visual>
    <inertial>
      <origin xyz="0 0 0" rpy="0 1.5707 1.5707"/>
      <mass value="5"/>
      <cylinder_inertia m="5" r="0.095" h="0.025"/>
      <inertia
        ixx="1.0" ixy="0.0" ixz="0.0"
        iyy="1.0" iyz="0.0"
        izz="1.0"/>
    </inertial>
  </link>

  <link name="right_wheel"> 
    <!--origin xyz="0.1 -0.13 0.1" rpy="0 1.5707 1.5707"/-->
   <collision name="collision">
      <origin xyz="0 0 0" rpy="0 1.5707 1.5707"/>
      <geometry>
        <cylinder radius="0.095" length="0.025"/>
      </geometry>
    </collision>
    <visual name="right_wheel_visual">
      <origin xyz="0 0 0" rpy="0 1.5707 1.5707"/>
      <geometry>
        <cylinder radius="0.095" length="0.025"/>
      </geometry>
    </visual>
    <inertial>
      <origin xyz="0 0 0" rpy="0 1.5707 1.5707"/>
      <mass value="5"/>
      <cylinder_inertia m="5" r="0.095" h="0.025"/>
      <inertia
        ixx="1.0" ixy="0.0" ixz="0.0"
        iyy="1.0" iyz="0.0"
        izz="1.0"/>
    </inertial>
  </link>

  <joint type="continuous" name="left_wheel_hinge">
    <origin xyz="0.1 0.11 -0.01" rpy="0 0 0"/>
    <child link="left_wheel"/>
    <parent link="chassis"/>
    <axis xyz="0 1 0" rpy="0 0 0"/>
    <limit effort="100" velocity="100"/>
    <joint_properties damping="0.0" friction="0.0"/>
  </joint>

  <joint type="continuous" name="right_wheel_hinge">
    <origin xyz="0.1 -0.11 -0.01" rpy="0 0 0"/>
    <child link="right_wheel"/>
    <parent link="chassis"/>
    <axis xyz="0 1 0" rpy="0 0 0"/>
    <limit effort="100" velocity="100"/>
    <joint_properties damping="0.0" friction="0.0"/>
  </joint>

  <joint name="camera_joint" type="fixed">
    <axis xyz="0 1 0" />
    <origin xyz=".2 0.025 0" rpy="0 0 0"/>
    <parent link="chassis"/>
    <child link="camera"/>
  </joint>


  <link name="camera">
    <collision>
      <origin xyz="0 0 0" rpy="0 0 0"/>
      <geometry>
        <box size="0.05 0.05 0.05"/>
      </geometry>
    </collision>

    <visual>
      <origin xyz="0 0 0" rpy="0 0 0"/>
      <geometry>
        <box size="0.05 0.05 0.05"/>
      </geometry>
      <material name="green"/>
    </visual>

    <inertial>
      <mass value="0.1" />
      <origin xyz="0 0 0" rpy="0 0 0"/>
      <box_inertia m="0.1" x="0.05" y="0.05" z="0.05" />
      <inertia ixx="1e-6" ixy="0" ixz="0" iyy="1e-6" iyz="0" izz="1e-6" />
    </inertial>
  </link>

  <joint name="imu_joint" type="fixed">
    <axis xyz="0 1 0"/>
    <origin xyz="0 -0.07 0.05" rpy="0 0 0"/>
    <parent link="chassis"/>
    <child link="imu_link"/>
  </joint>

  <link name="imu_link">
    <inertial>
      <mass value="0.001"/>
      <origin rpy="0 0 0" xyz="0 0 0"/>
      <inertia ixx="0.0001" ixy="0" ixz="0" iyy="0.000001" iyz="0" izz="0.0001"/>
    </inertial>
    <visual>
      <origin rpy="0 0 0" xyz="0 0 0"/>
      <geometry>
        <box size="0.021 0.016 0.00164"/>
      </geometry>
      <material name="black_metal">
        <color rgba="0.1 0.1 0.1 1"/>
      </material>
    </visual>
    <collision>
      <origin rpy="0 0 0" xyz="0 0 0"/>
      <geometry>
        <box size="0.021 0.016 0.0016"/>
      </geometry>
    </collision>
  </link>

  <joint name="ultrasonic_joint_f" type="fixed">
    <axis xyz="0 1 0" />
    <origin xyz="0.15 0 0.08" rpy="0 0 0"/>
    <parent link="chassis"/>
    <child link="ultrasonic_front"/>
  </joint>
  
  <joint name="ultrasonic_joint_f_l" type="fixed">
    <axis xyz="0 1 0" />
    <origin xyz="0.15 0.05 0.08" rpy="0 0 0.7"/>
    <parent link="chassis"/>
    <child link="ultrasonic_front_left"/>
  </joint>

  <joint name="ultrasonic_joint_f_r" type="fixed">
    <axis xyz="0 1 0" />
    <origin xyz="0.15 -0.05 0.08" rpy="0 0 -0.7"/>
    <parent link="chassis"/>
    <child link="ultrasonic_front_right"/>
  </joint>

  <joint name="ultrasonic_joint_l" type="fixed">
    <axis xyz="0 1 0" />
    <origin xyz="0.15 0.1 0.08" rpy="0 0 1.44"/>
    <parent link="chassis"/>
    <child link="ultrasonic_left"/>
  </joint>


  <joint name="ultrasonic_joint_r" type="fixed">
    <axis xyz="0 1 0" />
    <origin xyz="0.15 -0.1 0.08" rpy="0 0 -1.44"/>
    <parent link="chassis"/>
    <child link="ultrasonic_right"/>
  </joint>

  <!-- <joint name="radar_joint" type="fixed">
    <axis xyz="0 1 0" />
    <origin xyz="0 0 0.1" rpy="0 0 -1.57"/>
    <parent link="chassis"/>
    <child link="radar"/>
  </joint> -->


  <!-- Self made radar with servo -->
  <!-- <link name="radar">
    <visual>
      <origin xyz="0 0 0" rpy="0 0 0"/>
      <geometry>
        <mesh filename="package://mybot_description/meshes/hokuyo.dae"/>
      </geometry>
    </visual>

    <inertial>
      <mass value="1e-5" />
      <origin xyz="0 0 0" rpy="0 0 0"/>
      <inertia ixx="1e-6" ixy="0" ixz="0" iyy="1e-6" iyz="0" izz="1e-6" />
    </inertial>
  </link> -->
 
  <!-- Hokuyo Laser -->
  <link name="ultrasonic_front">
    <visual>
      <origin xyz="0 0 0" rpy="0 0 0"/>
      <geometry>
        <mesh filename="package://mybot_description/meshes/hokuyo.dae"/>
      </geometry>
    </visual>

    <inertial>
      <mass value="1e-5" />
      <origin xyz="0 0 0" rpy="0 0 0"/>
      <inertia ixx="1e-6" ixy="0" ixz="0" iyy="1e-6" iyz="0" izz="1e-6" />
    </inertial>
  </link>
  
  <link name="ultrasonic_front_right">
    <visual>
      <origin xyz="0 0 0" rpy="0 0 0"/>
      <geometry>
        <mesh filename="package://mybot_description/meshes/hokuyo.dae"/>
      </geometry>
    </visual>

    <inertial>
      <mass value="1e-5" />
      <origin xyz="0 0 0" rpy="0 0 0"/>
      <inertia ixx="1e-6" ixy="0" ixz="0" iyy="1e-6" iyz="0" izz="1e-6" />
    </inertial>
  </link>
  
  <link name="ultrasonic_front_left">
    <visual>
      <origin xyz="0 0 0" rpy="0 0 0"/>
      <geometry>
        <mesh filename="package://mybot_description/meshes/hokuyo.dae"/>
      </geometry>
    </visual>

    <inertial>
      <mass value="1e-5" />
      <origin xyz="0 0 0" rpy="0 0 0"/>
      <inertia ixx="1e-6" ixy="0" ixz="0" iyy="1e-6" iyz="0" izz="1e-6" />
    </inertial>
  </link>
  
  <link name="ultrasonic_right">
    <visual>
      <origin xyz="0 0 0" rpy="0 0 0"/>
      <geometry>
        <mesh filename="package://mybot_description/meshes/hokuyo.dae"/>
      </geometry>
    </visual>

    <inertial>
      <mass value="1e-5" />
      <origin xyz="0 0 0" rpy="0 0 0"/>
      <inertia ixx="1e-6" ixy="0" ixz="0" iyy="1e-6" iyz="0" izz="1e-6" />
    </inertial>
  </link>

  <link name="ultrasonic_left">
    <visual>
      <origin xyz="0 0 0" rpy="0 0 0"/>
      <geometry>
        <mesh filename="package://mybot_description/meshes/hokuyo.dae"/>
      </geometry>
    </visual>

    <inertial>
      <mass value="1e-5" />
      <origin xyz="0 0 0" rpy="0 0 0"/>
      <inertia ixx="1e-6" ixy="0" ixz="0" iyy="1e-6" iyz="0" izz="1e-6" />
    </inertial>
  </link>


</robot>
